Workbook

Sheet 표지
B2: VCF Private AI 사이징과 TCO 계산 워크북
B5: 목적: 입력 시트의 값을 채우면 동시성, GPU, 호스트, VKS 노드, 스토리지, TCO 수량이 수식으로 산출됩니다.
B7: [중요]
B8: - 성능 작동점(요청 동시성, 첫 토큰 시간, 토큰 간 지연)의 기본값은 공개 측정값이며, 자사 PoC 실측으로 바꿔야 합니다(가이드 06 6.5절).
B9: - 1인당 질의 수와 피크/평균비의 기본값은 근거 없는 가정값입니다. 자사 로그로 실측하세요(부록 A2.1).
B10: - 금액은 싣지 않습니다. TCO 시트는 수량까지 계산하고, 단가 칸은 견적으로 채웁니다(부록 A3).
B12: [시트 구성]
B13: - 입력: 자사 상황에 맞춰 정하는 값(파란 글씨)
B14: - 상수: 플랫폼 규칙과 보수 계수. 특별한 사유가 없으면 바꾸지 않습니다
B15: - 산정: 계산 결과와 점검 결과
B16: - TCO: 라이선스와 하드웨어 수량, 견적 단가 입력 칸
B18: [색상 약속]
... B28: 비공식 문서이며 벤더 공식 입장이 아닙니다. 모든 수치는 어림이며 실측과 견적으로 다시 확인하세요.

Sheet 입력
B1: 입력값 (자사 상황에 맞춰 파란 셀을 변경)
A2: 워크로드 (부록 A2.1)
B3: 도구를 배포받는 인원 | C3: 5000 | D3: 명
B4: 일 활성 비율 | C4: 0.3 | E4: 배포 인원 기준 업무일 평균. 참고 범위와 구하는 법은 A2.1
B5: 활성 사용자 1인당 업무일 질의 | C5: 10 | D5: 회 | E5: 가정값. 공개 근거 없음, 관리 콘솔이나 게이트웨이 로그로 실측
B6: 업무시간 | C6: 8 | D6: 시간 | E6: 대화형 트래픽의 업무시간 집중(A2.1)
B7: 피크/평균비 | C7: 3 | E7: 공개 근거 없는 보수 가정. 시간 단위 피크 계수를 실측
B8: 버스트 헤드룸 | C8: 0.3 | E8: A2.1
A9: 토큰 (부록 A2.2)
B10: 시스템 프롬프트 | C10: 500 | D10: 토큰
B11: 사용자 질문 | C11: 100 | D11: 토큰
B12: 대화 이력 | C12: 400 | D12: 토큰
B13: 청크 크기 | C13: 512 | D13: 토큰
B14: 최종 검색 결과 개수(리랭크 후) | C14: 6 | D14: 개
B15: 출력 토큰 | C15: 500 | D15: 토큰 | E15: 보수 산정. 평균 산정이면 250–300
B16: 한국어 토큰 팽창 계수 | C16: 1 | D16: 배 | E16: 위 토큰을 한국어로 이미 셌으면 1.0, 영어 기준 어림이면 1.3–1.7(A2.2)
A17: 모델 (부록 A2.4, A2.5)
B18: 모델 설명 | C18: 70B dense (예: Llama 3.1 70B) | E18: 산정에는 아래 숫자만 쓰임
B19: 총 파라미터 수 | C19: 70 | D19: B(십억)
B20: 가중치 정밀도 바이트 | C20: 1 | D20: byte | E20: FP8=1, FP16/BF16=2, 4비트=0.5
B21: 레이어 수 | C21: 80 | E21: config.json num_hidden_layers
B22: KV 헤드 수 | C22: 8 | E22: config.json num_key_value_heads
B23: head_dim | C23: 128 | E23: config.json head_dim 또는 hidden_size ÷ 어텐션 헤드 수
B24: KV 캐시 정밀도 바이트 | C24: 2 | D24: byte | E24: BF16 KV=2, FP8 KV=1
A25: 성능 작동점 (PoC 실측으로 교체, 부록 A2.3)
B26: 측정 조건: 입력 토큰 | C26: 5000 | D26: 토큰 | E26: 아래 값을 잰 조건
B27: 측정 조건: 출력 토큰 | C27: 500 | D27: 토큰
B28: 지연 목표를 지키는 복제본당 동시성 | C28: 50 | D28: 요청 | E28: 기본값: NVIDIA NIM 공개 측정, 70B FP8, H100 4장, 동시성 50
B29: 그 동시성에서 첫 토큰 시간 | C29: 952 | D29: ms | E29: 동 측정 952.43ms
B30: 그 동시성에서 토큰 간 지연 | C30: 40.13 | D30: ms | E30: 동 측정 40.13ms
B31: 지연 목표: 첫 토큰 시간 | C31: 2000 | D31: ms | E31: A2.3
B32: 지연 목표: 토큰 간 지연 | C32: 100 | D32: ms | E32: A2.3 (초당 10토큰 이상)
A33: GPU와 호스트 (가이드 02, 04)
B34: GPU 메모리 | C34: 80 | D34: GB
B35: 복제본당 GPU | C35: 4 | D35: 장 | E35: 텐서 병렬 수. 호스트 안에서 NVLink로 묶임
B36: 호스트당 장착 GPU | C36: 4 | D36: 장
B37: 임베딩과 리랭커용 GPU | C37: 1 | D37: 장 | E37: CPU로 돌리면 0 (04 4.3절 N3)
B38: 가용성 추가 복제본(N+1) | C38: 1
B39: GPU 할당 방식 | C39: DirectPath | E39: DirectPath 또는 vGPU (07 7.2절)
B40: NIM 등 NVAIE 소프트웨어 사용 | C40: 예 | E40: 예 또는 아니오. 기본 성능 작동점이 NIM 측정값이라 기본값은 예
...

Sheet 상수
B1: 상수 (플랫폼 규칙과 보수 계수. 특별한 사유가 없으면 그대로)
A2: GPU 메모리 (가이드 02)
B3: gpu_memory_utilization | C3: 0.9 | E3: vLLM 기본값 (02 2.1절)
B4: GPU당 활성화와 오버헤드 | C4: 4 | D4: GB | E4: 어림
B5: GPU 메모리 ÷ 가중치 점검값 | C5: 2.5 | D5: 배 | E5: VCF 9.1 설계 PAIF-ACC-RCMD-001
A6: 가용성과 클러스터 (가이드 04)
B7: 모델 엔드포인트 최소 복제본 | C7: 2 | E7: VCF 9.1 PAIS 설계 PAIS-021
B8: PAIF 최소 GPU 호스트 | C8: 3 | D8: 대 | E8: PAIF 9.1 요건 (01 1.1절)
B9: 컨트롤 플레인 노드 | C9: 3 | E9: 운영 환경 3 (04 4.1절)
B10: 일반 워커 노드 | C10: 3 | E10: HA
B11: GPU 노드 오토스케일 헤드룸 | C11: 0.2 | E11: 04 4.4절
B12: 클러스터 수 | C12: 1 | E12: 격리 요구 시 증가 (04 4.5절)
B13: Supervisor 클러스터 한도 | C13: 500 | E13: 04 4.5절
B14: Supervisor 노드 한도 | C14: 4000 | E14: 04 4.5절
A15: 스토리지 (가이드 05)
B16: 벡터 float 바이트 | C16: 4 | D16: byte | E16: pgvector float32
B17: HNSW 인덱스 배수 | C17: 2 | D17: 배 | E17: 원시 벡터 대비 1.5–3배 (05 5.2절)
B18: 원문 전처리 사본 배수 | C18: 1.5 | D18: 배 | E18: 05 5.1절
B19: RAG 벡터 DB 저장 공식 비율 상한 | C19: 10 | D19: 배 | E19: 원문의 5–10배, VCF 9.1 설계 PAIF-ACC-RCMD-010
B20: vSAN 보호 오버헤드 배수 | C20: 1.5 | D20: 배 | E20: Auto-RAID (05 5.3절)
B21: 압축과 중복제거 절감 배수 | C21: 1 | D21: 배 | E21: 보수적으로 1.0
A22: 라이선스 (부록 A3)
B23: 소켓당 코어 최소수량 | C23: 16 | D23: 코어 | E23: 견적으로 확인

Sheet 산정
B1: 사이징 산정 (검은 셀은 수식, 수정 금지)
A2: 토큰 (A2.2)
B3: 요청당 입력 토큰 | C3: =(입력!$C$10+입력!$C$11+입력!$C$12+입력!$C$13*입력!$C$14)*입력!$C$16 -> 4072 | D3: 토큰
B4: 요청당 출력 토큰 | C4: =입력!$C$15*입력!$C$16 -> 500 | D4: 토큰
B5: 요청당 전체 토큰 | C5: =C3+C4 -> 4572 | D5: 토큰
B6: 측정 조건 대비 입력 길이 | C6: =IF(C3>입력!$C$26*1.1,"측정 조건보다 김: 처리 시간이 짧게 잡혔을 수 있음","측정 조건 이내") -> 측정 조건 이내
B7: 측정 조건 대비 출력 길이 | C7: =IF(C4>입력!$C$27*1.1,"측정 조건보다 김: 토큰 간 지연이 커질 수 있음","측정 조건 이내") -> 측정 조건 이내
A8: 지연과 처리 시간 (A2.3)
B9: 요청당 처리 시간 | C9: =(입력!$C$29+입력!$C$30*MAX(C4-1,0))/1000 -> 20.97687 | D9: 초 | E9: 첫 토큰 시간 + 토큰 간 지연 × 출력 토큰
B10: 지연 목표 점검 | C10: =IF(AND(입력!$C$29<=입력!$C$31,입력!$C$30<=입력!$C$32),"충족","미충족: 작동점 동시성을 낮춰 다시 측정") -> 충족
A11: 워크로드에서 동시성으로 (A2.1)
B12: 일 활성 사용자 | C12: =입력!$C$3*입력!$C$4 -> 1500 | D12: 명
B13: 일 요청 수 | C13: =C12*입력!$C$5 -> 15000 | D13: 건
B14: 피크 초당 요청 | C14: =C13/(입력!$C$6*3600)*입력!$C$7 -> 1.5625 | D14: req/s
B15: 피크 동시 요청 | C15: =C14*C9 -> 32.776359 | D15: 요청 | E15: 피크 초당 요청 × 요청당 처리 시간
B16: 설계 동시성 | C16: =ROUNDUP(C15*(1+입력!$C$8),0) -> 43 | D16: 요청
A17: 복제본 하나의 GPU 메모리 (가이드 02)
B18: 가중치 메모리 | C18: =입력!$C$19*입력!$C$20 -> 70 | D18: GB
B19: 복제본 가용 메모리 | C19: =입력!$C$35*입력!$C$34*상수!$C$3-입력!$C$35*상수!$C$4 -> 272 | D19: GB | E19: GPU 수 × 메모리 × utilization − 오버헤드
B20: 모델 적재 가능 | C20: =IF(C18<=C19,"예","아니오: 복제본당 GPU를 늘리거나 양자화") -> 예
B21: GPU 메모리 ÷ 가중치 | C21: =입력!$C$35*입력!$C$34/C18 -> 4.5714286 | D21: 배 | E21: 점검값 2.5 이상 권장
B22: 토큰당 KV 캐시 | C22: =2*입력!$C$21*입력!$C$22*입력!$C$23*입력!$C$24/1073741824 -> 0.00030517578 | D22: GiB
B23: 요청당 KV 캐시 | C23: =C22*C5 -> 1.3952637 | D23: GiB
B24: 메모리로 담을 수 있는 동시성 상한 | C24: =IF(C18>=C19,0,FLOOR((C19-C18)/C23,1)) -> 144 | D24: 요청
B25: 작동점 동시성 메모리 점검 | C25: =IF(입력!$C$28<=C24,"정상","작동점 동시성이 메모리 상한을 넘음") -> 정상
A26: 복제본과 GPU (가이드 02 2.5절)
B27: 부하를 받는 복제본 | C27: =ROUNDUP(C16/입력!$C$28,0) -> 1 | E27: 설계 동시성 ÷ 복제본당 동시성
B28: 총 복제본 | C28: =MAX(C27+입력!$C$38,상수!$C$7) -> 2 | E28: N+1과 최소 복제본 2 중 큰 값
B29: 추론 GPU | C29: =C28*입력!$C$35 -> 8 | D29: 장
B30: 사용 GPU 합계 | C30: =C29+입력!$C$37 -> 9 | D30: 장
A31: 물리 호스트 (가이드 04 4.1절)
B32: 복제본당 GPU와 호스트당 GPU | C32: =IF(입력!$C$35<=입력!$C$36,"정상","복제본이 호스트를 넘음: 호스트 간 병렬 필요") -> 정상
B33: GPU 호스트 | C33: =MAX(ROUNDUP(C30/입력!$C$36,0),상수!$C$8) -> 3 | D33: 대 | E33: PAIF 최소 3대 반영
B34: 장착 GPU | C34: =C33*입력!$C$36 -> 12 | D34: 장 | E34: 하드웨어와 전력 산정 기준
B35: 물리 호스트 합계 | C35: =C33+IF(입력!$C$41="분리형",입력!$C$42,0) -> 3 | D35: 대
B36: GPU 호스트당 RAM 출발값(하한) | C36: =입력!$C$36*입력!$C$34*2 -> 640 | D36: GB | E36: GPU 메모리 합의 2–3배 (03 3.1절)
B37: GPU 호스트당 RAM 출발값(상한) | C37: =입력!$C$36*입력!$C$34*3 -> 960 | D37: GB
A38: VKS 노드 (가이드 04)
B39: GPU 워커 노드 | C39: =C28+IF(입력!$C$37>0,1,0) -> 3 | D39: VM | E39: 복제본당 1노드 + 임베딩 노드
B40: GPU 워커 노드(오토스케일 상한) | C40: =ROUNDUP(C39*(1+상수!$C$11),0) -> 4 | D40: VM
...

Sheet TCO
B1: TCO 수량 골격 (금액은 견적 단가로 채움, 부록 A3)
A2: 수량 산정
B3: 호스트당 라이선스 코어 | C3: =MAX(입력!$C$43,입력!$C$44*상수!$C$23) -> 64 | D3: 코어 | E3: MAX(실제 코어, 소켓 × 최소수량)
B4: 총 라이선스 코어 | C4: =산정!C35*C3 -> 192 | D4: 코어 | E4: 물리 호스트 합계 기준 (07 7.2절)
B5: NVAIE 대상 GPU | C5: =IF(OR(입력!$C$39="vGPU",입력!$C$40="예"),산정!C34,0) -> 12 | D5: 장 | E5: vGPU나 NIM을 쓰면 장착 GPU 전수, DirectPath와 오픈소스 스택이면 0 (07 7.2절)
A7: 비용 항목 (노란 칸에 견적 단가를 넣으면 소계 계산)
B8: 항목 | C8: 수량 | D8: 단가(견적 입력) | E8: 소계 | F8: 메모
B9: VCF 코어 구독 | C9: =C4 -> 192 | E9: =IF(D9="","견적 입력 필요",C9*D9) -> 견적 입력 필요 | F9: 코어/년, PAIF 포함(이중 계상 금지)
B10: NVAIE(GPU당) | C10: =C5 -> 12 | E10: =IF(D10="","견적 입력 필요",C10*D10) -> 견적 입력 필요 | F10: GPU/년, NVIDIA 별도. 0이면 불필요
B11: DSM | C11: =1 -> 1 | E11: =IF(D11="","견적 입력 필요",C11*D11) -> 견적 입력 필요 | F11: VCF 권한 조건 확인 (A3.1)
B12: GPU | C12: =산정!C34 -> 12 | E12: =IF(D12="","견적 입력 필요",C12*D12) -> 견적 입력 필요 | F12: 장착 GPU 기준, 상각연수로 나눔 (07 7.3절)
B13: GPU 서버 | C13: =산정!C33 -> 3 | E13: =IF(D13="","견적 입력 필요",C13*D13) -> 견적 입력 필요 | F13: 물리 서버 수, 상각연수로 나눔
B14: 비GPU 서버 | C14: =IF(입력!$C$41="분리형",입력!$C$42,0) -> 0 | E14: =IF(D14="","견적 입력 필요",C14*D14) -> 견적 입력 필요 | F14: 분리형일 때만
B15: 스토리지(GB) | C15: =산정!C53 -> 1935 | E15: =IF(D15="","견적 입력 필요",C15*D15) -> 견적 입력 필요 | F15: 예산 상한 기준 (05 5.5절)
B16: 네트워크와 스위치 | C16: =1 -> 1 | E16: =IF(D16="","견적 입력 필요",C16*D16) -> 견적 입력 필요 | F16: 토폴로지 (05 5.4절)
B17: 전력(연) | C17: =산정!C34 -> 12 | E17: =IF(D17="","견적 입력 필요",C17*D17) -> 견적 입력 필요 | F17: GPU 소비전력 × PUE (07 7.5절)
B18: 유지보수와 지원 | C18: =1 -> 1 | E18: =IF(D18="","견적 입력 필요",C18*D18) -> 견적 입력 필요 | F18: 계약
B19: 인력(선택) | C19: =0 -> 0 | E19: =IF(D19="","견적 입력 필요",C19*D19) -> 견적 입력 필요 | F19: 국내는 보통 제외. 넣을 때는 온프레미스와 클라우드에 같은 기준 적용
B20: 도입과 이행 | C20: =1 -> 1 | E20: =IF(D20="","견적 입력 필요",C20*D20) -> 견적 입력 필요 | F20: 일회성
B22: 단가(노란 칸)는 이 워크북이 제시하지 않습니다. 부록 A3 견적 요청 체크리스트로 채우고 출처를 기록하세요.
